# 线程池异常捕获

# 1. 异常处理的思路

JVM线程设计理念:

    线程是独立执行的代码片段，线程的问题应该由线程自己来解决，而不要委托到外部

异常处理的思想：

    线程方法的异常（checked和unchecked），都应该在线程代码边界之内(run方法内)进行try-catch，并处理掉，防止异常逃逸


基于JVM的设计理念，可以发现线程不允许抛出checked exception，但运行时异常不可避免

出现异常时异步线程会结束，主线程根本无从感知，更别提捕获从其他线程中逃逸的异常

# 2. 异常逃逸

## **2.1 Thread**

```java
public static void main(String[] args) {
    try {
        Thread t1 = new Thread(() -> System.out.println(1 / 0));
    } catch (Exception ex) {
        // 企图在主线程捕获t1线程的异常
        System.out.println("main thread catch ex");
    }
}
```

在上述代码中，t1线程将照常将"ArithmeticException：/by zero“的堆栈日志打印到控制台上，main线程并不能捕获到t1逃逸的异常

解决方案：

```java
// 1. 为t1设置未捕获异常的统一处理器
public static void main(String[] args) {
    Thread t1 = new Thread(() -> System.out.println(1 / 0));
    
    t1.setUncaughtExceptionHandler((t, e) -> {
        System.out.println("t1 caught own exception");
    });

    t1.start();
}
```

```java
// 2. 在t1中自己处理异常（可通过装饰器将try catch进行装饰）
public static void main(String[] args) {
    Thread t1 = new Thread(() -> {
        try {
            System.out.println(1 / 0);
        } catch (Exception ex) {
            System.out.println("t1 caught own exception");
        }
    });
    t1.start();
}
```

## **2.2 线程池**

本质上与Thread没有差别，**在边界内try-catch总是能保证到捕获效果**，这里专门提一下线程池中setUncaughtException()方法可能会失效的坑

### **2.2.1 设置Handler的时机**

```java
private static final ExecutorService exec = Executors.newSingleThreadExecutor();

public static void main(String[] args) {
    Thread t1 = new Thread(() -> System.out.println(1 / 0));
    t1.setUncaughtException((t, e) -> {
        System.out.println("t1 sovle own exception");
    });
    exec.execute(t1);
}
```

上述做法不妥的地方在于线程池会在execute时候调用addWorker，通过t1的接口行为（run方法）创建一个新的Thread类，使得设置的Handler失效

=>

```java
private static final ExecutorService exec = Executors.newSingleThreadExecutor();

public static void main(String[] args) {
    Thread t1 = new Thread(() -> {
        // 在线程池调度执行时，再动态的线程设置Handler
        Thread.currentThread().setUncaughtException((t, e) -> {
            System.out.println("t1 sovle own exception");
        });
        System.out.println(1 / 0);
    });
    exec.execute(t1);
}
```

### **2.2.2 execute(runnable)与submit(runnable)**

```java
private static final ExecutorService executorService = Executors.newSingleThreadExecutor();

public static void main(String[] args) {
    Thread t1 = new Thread(() -> {
        Thread.currentThread().setUncaughtExceptionHandler((t, e) -> {
            System.out.println("@!?@!");
        });
        System.out.println(1 / 0);
    });
    executorService.submit();
}
```

结果：控制台没有任何错误输出

原因：submit()方法是调用execute()实现任务执行的，但是在调用execute()之前，**会将任务封装进FutureTask类中，最终工作线程执行的是FutureTask的run方法**

```java
// AbstractExecutorService.java
public <T> Future<T> submit(Callable<T> task) {
    if (task == null) throw new NullPointerException();
    // 封装
    RunnableFuture<T> ftask = newTaskFor(task);
    execute(ftask);
    return ftask;
}
```

FutureTask会将正常结果、异常结果都作为自己的任务状态值的一部分，需要通过Future.get才能重新抛出异常

```java
// FutureTask.java
public void run() {
   // ...
    try {
        Callable<V> c = callable;
        if (c != null && state == NEW) {
            V result;
            boolean ran;
            try {
                result = c.call();
                ran = true;
            } catch (Throwable ex) {
                result = null;
                ran = false;
                // 此处调用setException方法
                setException(ex);
            }
           // ...
        }
    } finally {
       // ...
    }
}

protected void setException(Throwable t) {
    if (UNSAFE.compareAndSwapInt(this, stateOffset, NEW, COMPLETING)) {
        // 在此处吞掉异常
        outcome = t;
        UNSAFE.putOrderedInt(this, stateOffset, EXCEPTIONAL); // final state
        finishCompletion();
    }
}
```

使用Future.get的方式或多或少会导致阻塞调用，不推荐使用，在这种情况下应该使用try-catch进行处理

**execute()方法在不同的线程池接口中有不同实现，比如下述要讲的Scheduled线程池也会吞掉异常，但本质思路就是FutureTask会将结果（无论是否正常）都作为状态进行封装，吞掉异常**

### **2.2.3 ScheduledThreadPoolExecutor吞掉异常*

```java
private static final ScheduledExecutorService exec = new ScheduledThreadPoolExecutor(4);

public static void main(String[] args) {
    Thread t1 = new Thread(() -> {
        System.out.println(1 / 0);
    });
    exec.execute(t1);
}
```

结果: 与上述的submit()一致

原因：ScheduledThreadPoolExecutor接口的execute调用了schedule方法，而schedule方法会将任务封装为RunnableScheduledFuture（implements Future）

# 3. 解决方案（总结）

在Thread中可以使用UncaughtExceptionHanlder来实现默认的异常处理机制，以达到更好的代码整洁效果

但是在使用线程池时，使用UncaughtExceptionHandler并不合适，所以try-catch不可避免

为了整洁期间，可以通过装饰线程类的方式将try-catch进行封装，在提交/执行线程到线程池时使用装饰类

```java
public abstract class DecorateTask implements Runnable {
    public abstract void doRun();

    @Override
    public void run() {
        try {
            doRun();
        } catch (Throwable e) {
            // 进行处理
        }
    }
}

```

# 参考资料
- [ScheduledThreadPoolExecutor 吞异常](https://blog.csdn.net/weixin_30466421/article/details/97777904)
- [JAVA多线程之UncaughtExceptionHandler——处理非正常的线程中止](https://www.cnblogs.com/fanguangdexiaoyuer/p/11752123.html)


- [多线程中的异常处理](https://www.cnblogs.com/rouqinglangzi/p/10843701.html)

- [ScheduledThreadPoolExecutor Java 线程池吞掉未捕获异常](https://blog.csdn.net/mathcoder23/article/details/108725410)